<?xml version="1.0" encoding="utf-8"?>
<robot
  xmlns:xacro="http://www.ros.org/wiki/xacro"
  name="trailer">

  <xacro:include filename="$(find trailer_description)/urdf/trailer_gazebo.xacro"/>
  <xacro:include filename="$(find trailer_description)/urdf/trailer_ros2_control.xacro"/>

  <link name="base_footprint"/>  
  <link
    name="base_link">
    <inertial>
      <origin
        xyz="0.0145343749103901 -4.8067090025433E-11 0.504525903309878"
        rpy="0 0 0" />
      <mass
        value="5621.45261479066" />
      <inertia
        ixx="1504.39932306857"
        ixy="5.67577165358734E-07"
        ixz="-97.6855056473575"
        iyy="7926.87309013488"
        iyz="-6.11751972034413E-08"
        izz="8441.84332873847" />
    </inertial>
    <visual>
      <origin
        xyz="0 0 0"
        rpy="0 0 0" />
      <geometry>
        <mesh
          filename="package://trailer_description/meshes/base_link.STL" />
      </geometry>
      <material
        name="">
        <color
          rgba="0.792156862745098 0.819607843137255 0.933333333333333 1" />
      </material>
    </visual>
    <collision>
      <origin
        xyz="0 0 0"
        rpy="0 0 0" />
      <geometry>
        <mesh
          filename="package://trailer_description/meshes/base_link.STL" />
      </geometry>
    </collision>
  </link>
  <joint name="base_joint" type="fixed">
    <origin xyz="0 0 0.28575" rpy="0 0 0"/>
    <parent link="base_footprint"/>
    <child link="base_link"/>
  </joint>
  <link
    name="left_linkage">
    <inertial>
      <origin
        xyz="2.01833246560312E-07 0.086617432235983 0.114144894811922"
        rpy="0 0 0" />
      <mass
        value="4.04562727792638" />
      <inertia
        ixx="0.140037164042005"
        ixy="5.57435821298368E-08"
        ixz="-2.08850902365895E-08"
        iyy="0.0827902917589043"
        iyz="0.0400096165626049"
        izz="0.0604906292211796" />
    </inertial>
    <visual>
      <origin
        xyz="0 0 0"
        rpy="0 0 0" />
      <geometry>
        <mesh
          filename="package://trailer_description/meshes/left_linkage.STL" />
      </geometry>
      <material
        name="">
        <color
          rgba="0.792156862745098 0.819607843137255 0.933333333333333 1" />
      </material>
    </visual>
    <collision>
      <origin
        xyz="0 0 0"
        rpy="0 0 0" />
      <geometry>
        <mesh
          filename="package://trailer_description/meshes/left_linkage.STL" />
      </geometry>
    </collision>
  </link>
  <joint
    name="left_linkage_joint"
    type="revolute">
    <origin
      xyz="1.46 0.385 0"
      rpy="0 0 0" />
    <parent
      link="base_link" />
    <child
      link="left_linkage" />
    <axis
      xyz="0 0 1" />
    <limit
      lower="-0.5"
      upper="0.5"
      effort="50"
      velocity="1.5" />
  </joint>
  <link
    name="front_left_wheel">
    <inertial>
      <origin
        xyz="0 0 0"
        rpy="0 0 0" />
      <mass
        value="74.1907633489725" />
      <inertia
        ixx="2.08218966287404"
        ixy="-1.30089087994337E-17"
        ixz="5.1605164674113E-17"
        iyy="3.08830412900736"
        iyz="7.48293486257905E-18"
        izz="2.08218966287404" />
    </inertial>
    <visual>
      <origin
        xyz="0 0 0"
        rpy="0 0 0" />
      <geometry>
        <mesh
          filename="package://trailer_description/meshes/front_left_wheel.STL" />
      </geometry>
      <material
        name="">
        <color
          rgba="0.792156862745098 0.819607843137255 0.933333333333333 1" />
      </material>
    </visual>
    <collision>
      <origin
        xyz="0 0 0"
        rpy="0 0 0" />
      <geometry>
        <mesh
          filename="package://trailer_description/meshes/front_left_wheel.STL" />
      </geometry>
    </collision>
  </link>
  <joint
    name="front_left_wheel_joint"
    type="continuous">
    <origin
      xyz="0 0.2275 0"
      rpy="0 0 0" />
    <parent
      link="left_linkage" />
    <child
      link="front_left_wheel" />
    <axis
      xyz="0 -1 0" />
    <limit
      effort="100"
      velocity="31.4" />
  </joint>
  <link
    name="right_linkage">
    <inertial>
      <origin
        xyz="-2.01833246560312E-07 -0.0866174322359837 0.114144894811921"
        rpy="0 0 0" />
      <mass
        value="4.04562727792638" />
      <inertia
        ixx="0.140037164042004"
        ixy="5.5743582091201E-08"
        ixz="2.08850901407819E-08"
        iyy="0.0827902917589041"
        iyz="-0.0400096165626044"
        izz="0.0604906292211791" />
    </inertial>
    <visual>
      <origin
        xyz="0 0 0"
        rpy="0 0 0" />
      <geometry>
        <mesh
          filename="package://trailer_description/meshes/right_linkage.STL" />
      </geometry>
      <material
        name="">
        <color
          rgba="0.792156862745098 0.819607843137255 0.933333333333333 1" />
      </material>
    </visual>
    <collision>
      <origin
        xyz="0 0 0"
        rpy="0 0 0" />
      <geometry>
        <mesh
          filename="package://trailer_description/meshes/right_linkage.STL" />
      </geometry>
    </collision>
  </link>
  <joint
    name="right_linkage_joint"
    type="revolute">
    <origin
      xyz="1.46 -0.385 0"
      rpy="0 0 0" />
    <parent
      link="base_link" />
    <child
      link="right_linkage" />
    <axis
      xyz="0 0 1" />
    <limit
      lower="-0.5"
      upper="0.5"
      effort="50"
      velocity="1.5" />
  </joint>
  <link
    name="front_right_wheel">
    <inertial>
      <origin
        xyz="0 0 0"
        rpy="0 0 0" />
      <mass
        value="74.1907633489725" />
      <inertia
        ixx="2.08218966287404"
        ixy="1.28145530038214E-18"
        ixz="-1.7099551738079E-16"
        iyy="3.08830412900736"
        iyz="-2.68534024933067E-18"
        izz="2.08218966287404" />
    </inertial>
    <visual>
      <origin
        xyz="0 0 0"
        rpy="0 0 0" />
      <geometry>
        <mesh
          filename="package://trailer_description/meshes/front_right_wheel.STL" />
      </geometry>
      <material
        name="">
        <color
          rgba="0.792156862745098 0.819607843137255 0.933333333333333 1" />
      </material>
    </visual>
    <collision>
      <origin
        xyz="0 0 0"
        rpy="0 0 0" />
      <geometry>
        <mesh
          filename="package://trailer_description/meshes/front_right_wheel.STL" />
      </geometry>
    </collision>
  </link>
  <joint
    name="front_right_wheel_joint"
    type="continuous">
    <origin
      xyz="0 -0.2275 0"
      rpy="0 0 0" />
    <parent
      link="right_linkage" />
    <child
      link="front_right_wheel" />
    <axis
      xyz="0 -1 0" />
    <limit
      effort="100"
      velocity="31.4" />
  </joint>
  <link
    name="rear_left_wheel">
    <inertial>
      <origin
        xyz="0 -1.11022302462516E-16 0"
        rpy="0 0 0" />
      <mass
        value="74.1907633489725" />
      <inertia
        ixx="2.08218966287404"
        ixy="-3.48598814788576E-15"
        ixz="9.86076131526265E-32"
        iyy="3.08830412900736"
        iyz="-1.23785934175428E-30"
        izz="2.08218966287404" />
    </inertial>
    <visual>
      <origin
        xyz="0 0 0"
        rpy="0 0 0" />
      <geometry>
        <mesh
          filename="package://trailer_description/meshes/rear_left_wheel.STL" />
      </geometry>
      <material
        name="">
        <color
          rgba="0.792156862745098 0.819607843137255 0.933333333333333 1" />
      </material>
    </visual>
    <collision>
      <origin
        xyz="0 0 0"
        rpy="0 0 0" />
      <geometry>
        <mesh
          filename="package://trailer_description/meshes/rear_left_wheel.STL" />
      </geometry>
    </collision>
  </link>
  <joint
    name="rear_left_wheel_joint"
    type="continuous">
    <origin
      xyz="-1.17 0.6125 0"
      rpy="0 0 0" />
    <parent
      link="base_link" />
    <child
      link="rear_left_wheel" />
    <axis
      xyz="0 1 0" />
    <limit
      effort="100"
      velocity="31.4" />
  </joint>
  <link
    name="rear_right_wheel">
    <inertial>
      <origin
        xyz="0 1.11022302462516E-16 0"
        rpy="0 0 0" />
      <mass
        value="74.1907633489725" />
      <inertia
        ixx="2.08218966287404"
        ixy="3.48598814788576E-15"
        ixz="9.86076131526265E-32"
        iyy="3.08830412900736"
        iyz="1.22529057414273E-30"
        izz="2.08218966287404" />
    </inertial>
    <visual>
      <origin
        xyz="0 0 0"
        rpy="0 0 0" />
      <geometry>
        <mesh
          filename="package://trailer_description/meshes/rear_right_wheel.STL" />
      </geometry>
      <material
        name="">
        <color
          rgba="0.792156862745098 0.819607843137255 0.933333333333333 1" />
      </material>
    </visual>
    <collision>
      <origin
        xyz="0 0 0"
        rpy="0 0 0" />
      <geometry>
        <mesh
          filename="package://trailer_description/meshes/rear_right_wheel.STL" />
      </geometry>
    </collision>
  </link>
  <joint
    name="rear_right_wheel_joint"
    type="continuous">
    <origin
      xyz="-1.17 -0.6125 0"
      rpy="0 0 0" />
    <parent
      link="base_link" />
    <child
      link="rear_right_wheel" />
    <axis
      xyz="0 1 0" />
    <limit
      effort="100"
      velocity="31.4" />
  </joint>
  <link
    name="trailer">
    <inertial>
      <origin
        xyz="-2.06473943000056 -9.13851883438585E-17 0.256889099220807"
        rpy="0 0 0" />
      <mass
        value="2715.11151397176" />
      <inertia
        ixx="634.919956534306"
        ixy="7.69341401721132E-14"
        ixz="9.2945345694552"
        iyy="1640.30654615615"
        iyz="5.72407813967429E-15"
        izz="2004.11171155846" />
    </inertial>
    <visual>
      <origin
        xyz="0 0 0"
        rpy="0 0 0" />
      <geometry>
        <mesh
          filename="package://trailer_description/meshes/trailer.STL" />
      </geometry>
      <material
        name="">
        <color
          rgba="0.792156862745098 0.819607843137255 0.933333333333333 1" />
      </material>
    </visual>
    <collision>
      <origin
        xyz="0 0 0"
        rpy="0 0 0" />
      <geometry>
        <mesh
          filename="package://trailer_description/meshes/trailer.STL" />
      </geometry>
    </collision>
  </link>
  <joint
    name="trailer_joint"
    type="revolute">
    <origin
      xyz="-2.46 0 0.15"
      rpy="0 0 0" />
    <parent
      link="base_link" />
    <child
      link="trailer" />
    <axis
      xyz="0 0 -1" />
    <limit
      lower="-1"
      upper="1"
      effort="200"
      velocity="0.5" />
  </joint>
  <link
    name="t_left_wheel">
    <inertial>
      <origin
        xyz="0 0 1.11022302462516E-16"
        rpy="0 0 0" />
      <mass
        value="74.1907633489725" />
      <inertia
        ixx="2.08218966287404"
        ixy="1.54577203395557E-16"
        ixz="-2.7725470652962E-17"
        iyy="3.08830412900736"
        iyz="1.28966559951787E-17"
        izz="2.08218966287404" />
    </inertial>
    <visual>
      <origin
        xyz="0 0 0"
        rpy="0 0 0" />
      <geometry>
        <mesh
          filename="package://trailer_description/meshes/t_left_wheel.STL" />
      </geometry>
      <material
        name="">
        <color
          rgba="0.792156862745098 0.819607843137255 0.933333333333333 1" />
      </material>
    </visual>
    <collision>
      <origin
        xyz="0 0 0"
        rpy="0 0 0" />
      <geometry>
        <mesh
          filename="package://trailer_description/meshes/t_left_wheel.STL" />
      </geometry>
    </collision>
  </link>
  <joint
    name="t_left_wheel_joint"
    type="continuous">
    <origin
      xyz="-2.2086 0.6125 -0.15"
      rpy="0 0 0" />
    <parent
      link="trailer" />
    <child
      link="t_left_wheel" />
    <axis
      xyz="0 -1 0" />
    <limit
      effort="100"
      velocity="31.4" />
  </joint>
  <link
    name="t_right_wheel">
    <inertial>
      <origin
        xyz="0 0 1.11022302462516E-16"
        rpy="0 0 0" />
      <mass
        value="74.1907633489725" />
      <inertia
        ixx="2.08218966287404"
        ixy="-1.11352546000203E-18"
        ixz="6.83908165898515E-17"
        iyy="3.08830412900736"
        iyz="1.38630298064868E-17"
        izz="2.08218966287404" />
    </inertial>
    <visual>
      <origin
        xyz="0 0 0"
        rpy="0 0 0" />
      <geometry>
        <mesh
          filename="package://trailer_description/meshes/t_right_wheel.STL" />
      </geometry>
      <material
        name="">
        <color
          rgba="0.792156862745098 0.819607843137255 0.933333333333333 1" />
      </material>
    </visual>
    <collision>
      <origin
        xyz="0 0 0"
        rpy="0 0 0" />
      <geometry>
        <mesh
          filename="package://trailer_description/meshes/t_right_wheel.STL" />
      </geometry>
    </collision>
  </link>
  <joint
    name="t_right_wheel_joint"
    type="continuous">
    <origin
      xyz="-2.2086 -0.6125 -0.15"
      rpy="0 0 0" />
    <parent
      link="trailer" />
    <child
      link="t_right_wheel" />
    <axis
      xyz="0 -1 0" />
    <limit
      effort="100"
      velocity="31.4" />
  </joint>
</robot>