<?xml version="1.0" encoding="utf-8"?>
<robot
  xmlns:xacro="http://www.ros.org/wiki/xacro"
  name="trailer">

  <xacro:include filename="$(find trailer_description)/urdf/trailer_gazebo.xacro"/>
  <xacro:include filename="$(find trailer_description)/urdf/trailer_ros2_control.xacro"/>

  <link name="base_footprint"/>  
  <link
    name="base_link">
    <inertial>
      <origin
        xyz="0.0151794504413044 -2.72871741278684E-16 0.504333281484515"
        rpy="0 0 0" />
      <mass
        value="5623.96238078164" />
      <inertia
        ixx="1505.2735842584"
        ixy="3.7224720704788E-14"
        ixz="-96.1203292275202"
        iyy="7932.64531285603"
        iyz="-2.22978883011256E-14"
        izz="8447.43080900142" />
    </inertial>
    <visual>
      <origin
        xyz="0 0 0"
        rpy="0 0 0" />
      <geometry>
        <mesh
          filename="package://trailer_description/meshes/base_link.STL" />
      </geometry>
      <material
        name="">
        <color
          rgba="0.792156862745098 0.819607843137255 0.933333333333333 1" />
      </material>
    </visual>
    <collision>
      <origin
        xyz="0 0 0"
        rpy="0 0 0" />
      <geometry>
        <mesh
          filename="package://trailer_description/meshes/base_link.STL" />
      </geometry>
    </collision>
  </link>
  <joint name="base_joint" type="fixed">
    <origin xyz="0 0 0.28575" rpy="0 0 0"/>
    <parent link="base_footprint"/>
    <child link="base_link"/>
  </joint>
  <link
    name="steer_left">
    <inertial>
      <origin
        xyz="0 0 1.11022302462516E-16"
        rpy="0 0 0" />
      <mass
        value="1.48283173249438" />
      <inertia
        ixx="0.0113467519863581"
        ixy="4.92526541296846E-36"
        ixz="0"
        iyy="0.00118626538599551"
        iyz="4.00998451212503E-35"
        izz="0.0113467519863581" />
    </inertial>
    <visual>
      <origin
        xyz="0 0 0"
        rpy="0 0 0" />
      <geometry>
        <mesh
          filename="package://trailer_description/meshes/steer_left.STL" />
      </geometry>
      <material
        name="">
        <color
          rgba="0.792156862745098 0.819607843137255 0.933333333333333 1" />
      </material>
    </visual>
    <collision>
      <origin
        xyz="0 0 0"
        rpy="0 0 0" />
      <geometry>
        <mesh
          filename="package://trailer_description/meshes/steer_left.STL" />
      </geometry>
    </collision>
  </link>
  <joint
    name="steer_left_joint"
    type="revolute">
    <origin
      xyz="1.46 0.6125 0"
      rpy="0 0 0" />
    <parent
      link="base_link" />
    <child
      link="steer_left" />
    <axis
      xyz="0 0 -1" />
    <limit
      lower="-0.5"
      upper="0.5"
      effort="50"
      velocity="1.5" />
  </joint>
  <link
    name="front_left_wheel">
    <inertial>
      <origin
        xyz="0 0 -1.11022302462516E-16"
        rpy="0 0 0" />
      <mass
        value="74.1907633489725" />
      <inertia
        ixx="2.08218966287404"
        ixy="6.07695317678125E-17"
        ixz="-3.14934790723029E-18"
        iyy="3.08830412900736"
        iyz="3.93136225252298E-18"
        izz="2.08218966287404" />
    </inertial>
    <visual>
      <origin
        xyz="0 0 0"
        rpy="0 0 0" />
      <geometry>
        <mesh
          filename="package://trailer_description/meshes/front_left_wheel.STL" />
      </geometry>
      <material
        name="">
        <color
          rgba="0.792156862745098 0.819607843137255 0.933333333333333 1" />
      </material>
    </visual>
    <collision>
      <origin
        xyz="0 0 0"
        rpy="0 0 0" />
      <geometry>
        <mesh
          filename="package://trailer_description/meshes/front_left_wheel.STL" />
      </geometry>
    </collision>
  </link>
  <joint
    name="front_left_wheel_joint"
    type="continuous">
    <origin
      xyz="0 0 0"
      rpy="0 0 0" />
    <parent
      link="steer_left" />
    <child
      link="front_left_wheel" />
    <axis
      xyz="0 1 0" />
      <limit
      effort="100"
      velocity="31.4" />
  </joint>
  <link
    name="steer_right">
    <inertial>
      <origin
        xyz="0 0 1.11022302462516E-16"
        rpy="0 0 0" />
      <mass
        value="1.48283173249438" />
      <inertia
        ixx="0.0113467519863581"
        ixy="4.92526541296846E-36"
        ixz="0"
        iyy="0.00118626538599551"
        iyz="4.00998451212503E-35"
        izz="0.0113467519863581" />
    </inertial>
    <visual>
      <origin
        xyz="0 0 0"
        rpy="0 0 0" />
      <geometry>
        <mesh
          filename="package://trailer_description/meshes/steer_right.STL" />
      </geometry>
      <material
        name="">
        <color
          rgba="0.792156862745098 0.819607843137255 0.933333333333333 1" />
      </material>
    </visual>
    <collision>
      <origin
        xyz="0 0 0"
        rpy="0 0 0" />
      <geometry>
        <mesh
          filename="package://trailer_description/meshes/steer_right.STL" />
      </geometry>
    </collision>
  </link>
  <joint
    name="steer_right_joint"
    type="revolute">
    <origin
      xyz="1.46 -0.6125 0"
      rpy="0 0 0" />
    <parent
      link="base_link" />
    <child
      link="steer_right" />
    <axis
      xyz="0 0 1" />
    <limit
      lower="-0.5"
      upper="0.5"
      effort="50"
      velocity="1.5" />
  </joint>
  <link
    name="front_right_wheel">
    <inertial>
      <origin
        xyz="0 0 -1.11022302462516E-16"
        rpy="0 0 0" />
      <mass
        value="74.1907633489725" />
      <inertia
        ixx="2.08218966287404"
        ixy="6.07695317678125E-17"
        ixz="1.71424910145489E-17"
        iyy="3.08830412900736"
        iyz="1.83241460922682E-18"
        izz="2.08218966287404" />
    </inertial>
    <visual>
      <origin
        xyz="0 0 0"
        rpy="0 0 0" />
      <geometry>
        <mesh
          filename="package://trailer_description/meshes/front_right_wheel.STL" />
      </geometry>
      <material
        name="">
        <color
          rgba="0.792156862745098 0.819607843137255 0.933333333333333 1" />
      </material>
    </visual>
    <collision>
      <origin
        xyz="0 0 0"
        rpy="0 0 0" />
      <geometry>
        <mesh
          filename="package://trailer_description/meshes/front_right_wheel.STL" />
      </geometry>
    </collision>
  </link>
  <joint
    name="front_right_wheel_joint"
    type="continuous">
    <origin
      xyz="0 0 0"
      rpy="0 0 0" />
    <parent
      link="steer_right" />
    <child
      link="front_right_wheel" />
    <axis
      xyz="0 1 0" />
      <limit
      effort="100"
      velocity="31.4" />
  </joint>
  <link
    name="rear_left_wheel">
    <inertial>
      <origin
        xyz="0 -1.11022302462516E-16 0"
        rpy="0 0 0" />
      <mass
        value="74.1907633489725" />
      <inertia
        ixx="2.08218966287404"
        ixy="-3.48598814788576E-15"
        ixz="9.86076131526265E-32"
        iyy="3.08830412900736"
        iyz="-1.23785934175428E-30"
        izz="2.08218966287404" />
    </inertial>
    <visual>
      <origin
        xyz="0 0 0"
        rpy="0 0 0" />
      <geometry>
        <mesh
          filename="package://trailer_description/meshes/rear_left_wheel.STL" />
      </geometry>
      <material
        name="">
        <color
          rgba="0.792156862745098 0.819607843137255 0.933333333333333 1" />
      </material>
    </visual>
    <collision>
      <origin
        xyz="0 0 0"
        rpy="0 0 0" />
      <geometry>
        <mesh
          filename="package://trailer_description/meshes/rear_left_wheel.STL" />
      </geometry>
    </collision>
  </link>
  <joint
    name="rear_left_wheel_joint"
    type="continuous">
    <origin
      xyz="-1.17 0.6125 0"
      rpy="0 0 0" />
    <parent
      link="base_link" />
    <child
      link="rear_left_wheel" />
    <axis
      xyz="0 1 0" />
    <limit
      effort="100"
      velocity="31.4" />
  </joint>
  <link
    name="rear_right_wheel">
    <inertial>
      <origin
        xyz="0 1.11022302462516E-16 0"
        rpy="0 0 0" />
      <mass
        value="74.1907633489725" />
      <inertia
        ixx="2.08218966287404"
        ixy="3.48598814788576E-15"
        ixz="9.86076131526265E-32"
        iyy="3.08830412900736"
        iyz="1.22529057414273E-30"
        izz="2.08218966287404" />
    </inertial>
    <visual>
      <origin
        xyz="0 0 0"
        rpy="0 0 0" />
      <geometry>
        <mesh
          filename="package://trailer_description/meshes/rear_right_wheel.STL" />
      </geometry>
      <material
        name="">
        <color
          rgba="0.792156862745098 0.819607843137255 0.933333333333333 1" />
      </material>
    </visual>
    <collision>
      <origin
        xyz="0 0 0"
        rpy="0 0 0" />
      <geometry>
        <mesh
          filename="package://trailer_description/meshes/rear_right_wheel.STL" />
      </geometry>
    </collision>
  </link>
  <joint
    name="rear_right_wheel_joint"
    type="continuous">
    <origin
      xyz="-1.17 -0.6125 0"
      rpy="0 0 0" />
    <parent
      link="base_link" />
    <child
      link="rear_right_wheel" />
    <axis
      xyz="0 1 0" />
    <limit
      effort="100"
      velocity="31.4" />
  </joint>
  <link
    name="trailer">
    <inertial>
      <origin
        xyz="-2.06473943000056 -9.59060549514745E-17 0.256889099220807"
        rpy="0 0 0" />
      <mass
        value="2715.11151397176" />
      <inertia
        ixx="634.919956534306"
        ixy="7.66014195843368E-14"
        ixz="9.29453456945521"
        iyy="1640.30654615615"
        iyz="4.53164968888437E-15"
        izz="2004.11171155846" />
    </inertial>
    <visual>
      <origin
        xyz="0 0 0"
        rpy="0 0 0" />
      <geometry>
        <mesh
          filename="package://trailer_description/meshes/trailer.STL" />
      </geometry>
      <material
        name="">
        <color
          rgba="0.792156862745098 0.819607843137255 0.933333333333333 1" />
      </material>
    </visual>
    <collision>
      <origin
        xyz="0 0 0"
        rpy="0 0 0" />
      <geometry>
        <mesh
          filename="package://trailer_description/meshes/trailer.STL" />
      </geometry>
    </collision>
  </link>
  <joint
    name="trailer_joint"
    type="revolute">
    <origin
      xyz="-2.46 0 0.15"
      rpy="0 0 0" />
    <parent
      link="base_link" />
    <child
      link="trailer" />
    <axis
      xyz="0 0 -1" />
    <limit
      lower="-1"
      upper="1"
      effort="200"
      velocity="0.5" />
  </joint>
  <link
    name="t_left_wheel">
    <inertial>
      <origin
        xyz="0 0 1.11022302462516E-16"
        rpy="0 0 0" />
      <mass
        value="74.1907633489725" />
      <inertia
        ixx="2.08218966287404"
        ixy="1.54577203395557E-16"
        ixz="-2.7725470652962E-17"
        iyy="3.08830412900736"
        iyz="1.28966559951787E-17"
        izz="2.08218966287404" />
    </inertial>
    <visual>
      <origin
        xyz="0 0 0"
        rpy="0 0 0" />
      <geometry>
        <mesh
          filename="package://trailer_description/meshes/t_left_wheel.STL" />
      </geometry>
      <material
        name="">
        <color
          rgba="0.792156862745098 0.819607843137255 0.933333333333333 1" />
      </material>
    </visual>
    <collision>
      <origin
        xyz="0 0 0"
        rpy="0 0 0" />
      <geometry>
        <mesh
          filename="package://trailer_description/meshes/t_left_wheel.STL" />
      </geometry>
    </collision>
  </link>
  <joint
    name="t_left_wheel_joint"
    type="continuous">
    <origin
      xyz="-2.2086 0.6125 -0.15"
      rpy="0 0 0" />
    <parent
      link="trailer" />
    <child
      link="t_left_wheel" />
    <axis
      xyz="0 -1 0" />
    <limit
      effort="100"
      velocity="31.4" />
  </joint>
  <link
    name="t_right_wheel">
    <inertial>
      <origin
        xyz="0 0 1.11022302462516E-16"
        rpy="0 0 0" />
      <mass
        value="74.1907633489725" />
      <inertia
        ixx="2.08218966287404"
        ixy="-1.11352546000203E-18"
        ixz="6.83908165898515E-17"
        iyy="3.08830412900736"
        iyz="1.38630298064868E-17"
        izz="2.08218966287404" />
    </inertial>
    <visual>
      <origin
        xyz="0 0 0"
        rpy="0 0 0" />
      <geometry>
        <mesh
          filename="package://trailer_description/meshes/t_right_wheel.STL" />
      </geometry>
      <material
        name="">
        <color
          rgba="0.792156862745098 0.819607843137255 0.933333333333333 1" />
      </material>
    </visual>
    <collision>
      <origin
        xyz="0 0 0"
        rpy="0 0 0" />
      <geometry>
        <mesh
          filename="package://trailer_description/meshes/t_right_wheel.STL" />
      </geometry>
    </collision>
  </link>
  <joint
    name="t_right_wheel_joint"
    type="continuous">
    <origin
      xyz="-2.2086 -0.6125 -0.15"
      rpy="0 0 0" />
    <parent
      link="trailer" />
    <child
      link="t_right_wheel" />
    <axis
      xyz="0 -1 0" />
    <limit
      effort="100"
      velocity="31.4" />
  </joint>
</robot>