<?xml version="1.0" encoding="utf-8"?>
<!-- This URDF was automatically created by SolidWorks to URDF Exporter! Originally created by Stephen Brawner (brawner@gmail.com) 
     Commit Version: 1.6.0-4-g7f85cfe  Build Version: 1.6.7995.38578
     For more information, please see http://wiki.ros.org/sw_urdf_exporter -->
<robot
  name="trailer_description">
  <link
    name="base_link">
    <inertial>
      <origin
        xyz="0.0151794504413043 -2.6956551943736E-16 0.504333281484515"
        rpy="0 0 0" />
      <mass
        value="5623.96238078164" />
      <inertia
        ixx="1505.2735842584"
        ixy="3.10657795280898E-14"
        ixz="-96.1203292275202"
        iyy="7932.64531285603"
        iyz="-3.10015617296073E-14"
        izz="8447.43080900142" />
    </inertial>
    <visual>
      <origin
        xyz="0 0 0"
        rpy="0 0 0" />
      <geometry>
        <mesh
          filename="package://trailer_description/meshes/base_link.STL" />
      </geometry>
      <material
        name="">
        <color
          rgba="0.792156862745098 0.819607843137255 0.933333333333333 1" />
      </material>
    </visual>
    <collision>
      <origin
        xyz="0 0 0"
        rpy="0 0 0" />
      <geometry>
        <mesh
          filename="package://trailer_description/meshes/base_link.STL" />
      </geometry>
    </collision>
  </link>
  <link
    name="steer_left">
    <inertial>
      <origin
        xyz="0 0 1.11022302462516E-16"
        rpy="0 0 0" />
      <mass
        value="1.48283173249438" />
      <inertia
        ixx="0.0113467519863581"
        ixy="4.92526541296846E-36"
        ixz="0"
        iyy="0.00118626538599551"
        iyz="4.00998451212503E-35"
        izz="0.0113467519863581" />
    </inertial>
    <visual>
      <origin
        xyz="0 0 0"
        rpy="0 0 0" />
      <geometry>
        <mesh
          filename="package://trailer_description/meshes/steer_left.STL" />
      </geometry>
      <material
        name="">
        <color
          rgba="0.792156862745098 0.819607843137255 0.933333333333333 1" />
      </material>
    </visual>
    <collision>
      <origin
        xyz="0 0 0"
        rpy="0 0 0" />
      <geometry>
        <mesh
          filename="package://trailer_description/meshes/steer_left.STL" />
      </geometry>
    </collision>
  </link>
  <joint
    name="steer_left_joint"
    type="revolute">
    <origin
      xyz="1.46 0.6125 0"
      rpy="0 0 0" />
    <parent
      link="base_link" />
    <child
      link="steer_left" />
    <axis
      xyz="0 0 -1" />
    <limit
      lower="-0.6"
      upper="0.6"
      effort="50"
      velocity="31.4" />
  </joint>
  <link
    name="front_left_wheel">
    <inertial>
      <origin
        xyz="0 0 -1.11022302462516E-16"
        rpy="0 0 0" />
      <mass
        value="74.1907633489725" />
      <inertia
        ixx="2.08218966287404"
        ixy="6.07695317678125E-17"
        ixz="-3.14934790723029E-18"
        iyy="3.08830412900736"
        iyz="3.93136225252298E-18"
        izz="2.08218966287404" />
    </inertial>
    <visual>
      <origin
        xyz="0 0 0"
        rpy="0 0 0" />
      <geometry>
        <mesh
          filename="package://trailer_description/meshes/front_left_wheel.STL" />
      </geometry>
      <material
        name="">
        <color
          rgba="0.792156862745098 0.819607843137255 0.933333333333333 1" />
      </material>
    </visual>
    <collision>
      <origin
        xyz="0 0 0"
        rpy="0 0 0" />
      <geometry>
        <mesh
          filename="package://trailer_description/meshes/front_left_wheel.STL" />
      </geometry>
    </collision>
  </link>
  <joint
    name="front_left_wheel_joint"
    type="continuous">
    <origin
      xyz="0 0 0"
      rpy="0 0 0" />
    <parent
      link="steer_left" />
    <child
      link="front_left_wheel" />
    <axis
      xyz="0 1 0" />
    <limit
      lower="0"
      upper="0"
      effort="100"
      velocity="31.4" />
  </joint>
  <link
    name="steer_right">
    <inertial>
      <origin
        xyz="0 0 1.11022302462516E-16"
        rpy="0 0 0" />
      <mass
        value="1.48283173249438" />
      <inertia
        ixx="0.0113467519863581"
        ixy="4.92526541296846E-36"
        ixz="0"
        iyy="0.00118626538599551"
        iyz="4.00998451212503E-35"
        izz="0.0113467519863581" />
    </inertial>
    <visual>
      <origin
        xyz="0 0 0"
        rpy="0 0 0" />
      <geometry>
        <mesh
          filename="package://trailer_description/meshes/steer_right.STL" />
      </geometry>
      <material
        name="">
        <color
          rgba="0.792156862745098 0.819607843137255 0.933333333333333 1" />
      </material>
    </visual>
    <collision>
      <origin
        xyz="0 0 0"
        rpy="0 0 0" />
      <geometry>
        <mesh
          filename="package://trailer_description/meshes/steer_right.STL" />
      </geometry>
    </collision>
  </link>
  <joint
    name="steer_right_joint"
    type="revolute">
    <origin
      xyz="1.46 -0.6125 0"
      rpy="0 0 0" />
    <parent
      link="base_link" />
    <child
      link="steer_right" />
    <axis
      xyz="0 0 1" />
    <limit
      lower="-0.6"
      upper="0.6"
      effort="50"
      velocity="31.4" />
  </joint>
  <link
    name="front_right_wheel">
    <inertial>
      <origin
        xyz="0 0 -1.11022302462516E-16"
        rpy="0 0 0" />
      <mass
        value="74.1907633489725" />
      <inertia
        ixx="2.08218966287404"
        ixy="6.07695317678125E-17"
        ixz="1.7142491014549E-17"
        iyy="3.08830412900736"
        iyz="1.83241460922682E-18"
        izz="2.08218966287404" />
    </inertial>
    <visual>
      <origin
        xyz="0 0 0"
        rpy="0 0 0" />
      <geometry>
        <mesh
          filename="package://trailer_description/meshes/front_right_wheel.STL" />
      </geometry>
      <material
        name="">
        <color
          rgba="0.792156862745098 0.819607843137255 0.933333333333333 1" />
      </material>
    </visual>
    <collision>
      <origin
        xyz="0 0 0"
        rpy="0 0 0" />
      <geometry>
        <mesh
          filename="package://trailer_description/meshes/front_right_wheel.STL" />
      </geometry>
    </collision>
  </link>
  <joint
    name="front_right_wheel_joint"
    type="continuous">
    <origin
      xyz="0 0 0"
      rpy="0 0 0" />
    <parent
      link="steer_right" />
    <child
      link="front_right_wheel" />
    <axis
      xyz="0 1 0" />
    <limit
      lower="0"
      upper="0"
      effort="100"
      velocity="31.4" />
  </joint>
  <link
    name="rear_left_wheel">
    <inertial>
      <origin
        xyz="0 -1.11022302462516E-16 0"
        rpy="0 0 0" />
      <mass
        value="74.1907633489725" />
      <inertia
        ixx="2.08218966287404"
        ixy="-3.48598814788576E-15"
        ixz="9.86076131526265E-32"
        iyy="3.08830412900736"
        iyz="-1.23785934175428E-30"
        izz="2.08218966287404" />
    </inertial>
    <visual>
      <origin
        xyz="0 0 0"
        rpy="0 0 0" />
      <geometry>
        <mesh
          filename="package://trailer_description/meshes/rear_left_wheel.STL" />
      </geometry>
      <material
        name="">
        <color
          rgba="0.792156862745098 0.819607843137255 0.933333333333333 1" />
      </material>
    </visual>
    <collision>
      <origin
        xyz="0 0 0"
        rpy="0 0 0" />
      <geometry>
        <mesh
          filename="package://trailer_description/meshes/rear_left_wheel.STL" />
      </geometry>
    </collision>
  </link>
  <joint
    name="rear_left_wheel_joint"
    type="continuous">
    <origin
      xyz="-1.17000000000001 0.612499999999998 0"
      rpy="0 0 0" />
    <parent
      link="base_link" />
    <child
      link="rear_left_wheel" />
    <axis
      xyz="0 1 0" />
    <limit
      lower="0"
      upper="0"
      effort="100"
      velocity="31.4" />
  </joint>
  <link
    name="rear_right_wheel">
    <inertial>
      <origin
        xyz="0 1.11022302462516E-16 0"
        rpy="0 0 0" />
      <mass
        value="74.1907633489725" />
      <inertia
        ixx="2.08218966287404"
        ixy="3.48598814788576E-15"
        ixz="9.86076131526265E-32"
        iyy="3.08830412900736"
        iyz="1.22529057414273E-30"
        izz="2.08218966287404" />
    </inertial>
    <visual>
      <origin
        xyz="0 0 0"
        rpy="0 0 0" />
      <geometry>
        <mesh
          filename="package://trailer_description/meshes/rear_right_wheel.STL" />
      </geometry>
      <material
        name="">
        <color
          rgba="0.792156862745098 0.819607843137255 0.933333333333333 1" />
      </material>
    </visual>
    <collision>
      <origin
        xyz="0 0 0"
        rpy="0 0 0" />
      <geometry>
        <mesh
          filename="package://trailer_description/meshes/rear_right_wheel.STL" />
      </geometry>
    </collision>
  </link>
  <joint
    name="rear_right_wheel_joint"
    type="continuous">
    <origin
      xyz="-1.17000000000001 -0.612499999999998 0"
      rpy="0 0 0" />
    <parent
      link="base_link" />
    <child
      link="rear_right_wheel" />
    <axis
      xyz="0 1 0" />
    <limit
      lower="0"
      upper="0"
      effort="100"
      velocity="31.4" />
  </joint>
  <link
    name="trailer">
    <inertial>
      <origin
        xyz="-2.06473943000057 -1.88968614925875E-16 0.256889099220807"
        rpy="0 0 0" />
      <mass
        value="2715.11151397176" />
      <inertia
        ixx="634.919956534306"
        ixy="7.61521195844811E-14"
        ixz="9.2945345694552"
        iyy="1640.30654615616"
        iyz="-6.09857971861188E-15"
        izz="2004.11171155847" />
    </inertial>
    <visual>
      <origin
        xyz="0 0 0"
        rpy="0 0 0" />
      <geometry>
        <mesh
          filename="package://trailer_description/meshes/trailer.STL" />
      </geometry>
      <material
        name="">
        <color
          rgba="0.792156862745098 0.819607843137255 0.933333333333333 1" />
      </material>
    </visual>
    <collision>
      <origin
        xyz="0 0 0"
        rpy="0 0 0" />
      <geometry>
        <mesh
          filename="package://trailer_description/meshes/trailer.STL" />
      </geometry>
    </collision>
  </link>
  <joint
    name="trailer_joint"
    type="revolute">
    <origin
      xyz="-2.46 0 0.15"
      rpy="0 0 0" />
    <parent
      link="base_link" />
    <child
      link="trailer" />
    <axis
      xyz="0 0 -1" />
    <limit
      lower="-1"
      upper="1"
      effort="200"
      velocity="0.5" />
  </joint>
  <link
    name="t_left_wheel">
    <inertial>
      <origin
        xyz="0 0 1.11022302462516E-16"
        rpy="0 0 0" />
      <mass
        value="74.1907633489725" />
      <inertia
        ixx="2.08218966287404"
        ixy="8.52829769795647E-18"
        ixz="-1.98584756901403E-17"
        iyy="3.08830412900736"
        iyz="7.03176605089594E-18"
        izz="2.08218966287404" />
    </inertial>
    <visual>
      <origin
        xyz="0 0 0"
        rpy="0 0 0" />
      <geometry>
        <mesh
          filename="package://trailer_description/meshes/t_left_wheel.STL" />
      </geometry>
      <material
        name="">
        <color
          rgba="0.792156862745098 0.819607843137255 0.933333333333333 1" />
      </material>
    </visual>
    <collision>
      <origin
        xyz="0 0 0"
        rpy="0 0 0" />
      <geometry>
        <mesh
          filename="package://trailer_description/meshes/t_left_wheel.STL" />
      </geometry>
    </collision>
  </link>
  <joint
    name="t_left_wheel_joint"
    type="continuous">
    <origin
      xyz="-2.20864 0.6125 -0.15"
      rpy="0 0 0" />
    <parent
      link="trailer" />
    <child
      link="t_left_wheel" />
    <axis
      xyz="-0.0225880418212614 -0.999744857634527 0" />
    <limit
      lower="0"
      upper="0"
      effort="100"
      velocity="31.4" />
  </joint>
  <link
    name="t_right_wheel">
    <inertial>
      <origin
        xyz="0 0 0"
        rpy="0 0 0" />
      <mass
        value="74.1907633489725" />
      <inertia
        ixx="2.08218966287404"
        ixy="-6.33759727710489E-18"
        ixz="2.13017845392221E-16"
        iyy="3.08830412900736"
        iyz="-6.070436904292E-18"
        izz="2.08218966287404" />
    </inertial>
    <visual>
      <origin
        xyz="0 0 0"
        rpy="0 0 0" />
      <geometry>
        <mesh
          filename="package://trailer_description/meshes/t_right_wheel.STL" />
      </geometry>
      <material
        name="">
        <color
          rgba="0.792156862745098 0.819607843137255 0.933333333333333 1" />
      </material>
    </visual>
    <collision>
      <origin
        xyz="0 0 0"
        rpy="0 0 0" />
      <geometry>
        <mesh
          filename="package://trailer_description/meshes/t_right_wheel.STL" />
      </geometry>
    </collision>
  </link>
  <joint
    name="t_right_wheel_joint"
    type="continuous">
    <origin
      xyz="-2.20864 -0.6125 -0.15"
      rpy="0 0 0" />
    <parent
      link="trailer" />
    <child
      link="t_right_wheel" />
    <axis
      xyz="-0.0225880418212613 -0.999744857634527 0" />
    <limit
      lower="0"
      upper="0"
      effort="100"
      velocity="31.4" />
  </joint>
  <link
    name="Left_ArUco_marker">
    <inertial>
      <origin
        xyz="0 0 0"
        rpy="0 0 0" />
      <mass
        value="0.00250000000000084" />
      <inertia
        ixx="1.04166666666702E-06"
        ixy="1.29701920048421E-24"
        ixz="8.16151537710328E-26"
        iyy="5.21041666666841E-07"
        iyz="-2.03287907341201E-23"
        izz="5.21041666666842E-07" />
    </inertial>
    <visual>
      <origin
        xyz="0 0 0"
        rpy="0 0 0" />
      <geometry>
        <mesh
          filename="package://trailer_description/meshes/Left_ArUco_marker.STL" />
      </geometry>
      <material
        name="">
        <color
          rgba="0.792156862745098 0.819607843137255 0.933333333333333 1" />
      </material>
    </visual>
    <collision>
      <origin
        xyz="0 0 0"
        rpy="0 0 0" />
      <geometry>
        <mesh
          filename="package://trailer_description/meshes/Left_ArUco_marker.STL" />
      </geometry>
    </collision>
  </link>
  <joint
    name="Left_ArUco_joint"
    type="fixed">
    <origin
      xyz="-0.84864 0.69 0.55991"
      rpy="0 0 0" />
    <parent
      link="trailer" />
    <child
      link="Left_ArUco_marker" />
    <axis
      xyz="0 0 0" />
  </joint>
  <link
    name="Right_ArUco_marker">
    <inertial>
      <origin
        xyz="0 0 0"
        rpy="0 0 0" />
      <mass
        value="0.00250000000000084" />
      <inertia
        ixx="1.04166666666702E-06"
        ixy="1.29701920048421E-24"
        ixz="8.16151537710327E-26"
        iyy="5.21041666666841E-07"
        iyz="-2.03287907341201E-23"
        izz="5.21041666666842E-07" />
    </inertial>
    <visual>
      <origin
        xyz="0 0 0"
        rpy="0 0 0" />
      <geometry>
        <mesh
          filename="package://trailer_description/meshes/Right_ArUco_marker.STL" />
      </geometry>
      <material
        name="">
        <color
          rgba="0.792156862745098 0.819607843137255 0.933333333333333 1" />
      </material>
    </visual>
    <collision>
      <origin
        xyz="0 0 0"
        rpy="0 0 0" />
      <geometry>
        <mesh
          filename="package://trailer_description/meshes/Right_ArUco_marker.STL" />
      </geometry>
    </collision>
  </link>
  <joint
    name="Right_ArUco_joint"
    type="fixed">
    <origin
      xyz="-0.84864 -0.69 0.55991"
      rpy="0 0 0" />
    <parent
      link="trailer" />
    <child
      link="Right_ArUco_marker" />
    <axis
      xyz="0 0 0" />
  </joint>
  <link
    name="u1_Link">
    <inertial>
      <origin
        xyz="2.22044604925031E-16 0 0"
        rpy="0 0 0" />
      <mass
        value="0.00176714586764422" />
      <inertia
        ixx="4.97009775274937E-08"
        ixy="6.44944990373328E-23"
        ixz="-1.28060738442034E-40"
        iyy="3.95767043274481E-08"
        iyz="9.95682444457783E-55"
        izz="3.95767043274481E-08" />
    </inertial>
    <visual>
      <origin
        xyz="0 0 0"
        rpy="0 0 0" />
      <geometry>
        <mesh
          filename="package://trailer_description/meshes/u1_Link.STL" />
      </geometry>
      <material
        name="">
        <color
          rgba="0.792156862745098 0.819607843137255 0.933333333333333 1" />
      </material>
    </visual>
    <collision>
      <origin
        xyz="0 0 0"
        rpy="0 0 0" />
      <geometry>
        <mesh
          filename="package://trailer_description/meshes/u1_Link.STL" />
      </geometry>
    </collision>
  </link>
  <joint
    name="u1_joint"
    type="fixed">
    <origin
      xyz="-2.16 0.6125 0.05"
      rpy="0 0 3.1416" />
    <parent
      link="base_link" />
    <child
      link="u1_Link" />
    <axis
      xyz="0 0 0" />
  </joint>
  <link
    name="u2_Link">
    <inertial>
      <origin
        xyz="4.44089209850063E-16 0 0"
        rpy="0 0 0" />
      <mass
        value="0.00176714586764422" />
      <inertia
        ixx="4.97009775274937E-08"
        ixy="-6.61984950467753E-23"
        ixz="6.44944990373324E-23"
        iyy="3.95767043274481E-08"
        iyz="-1.03497225198971E-37"
        izz="3.95767043274481E-08" />
    </inertial>
    <visual>
      <origin
        xyz="0 0 0"
        rpy="0 0 0" />
      <geometry>
        <mesh
          filename="package://trailer_description/meshes/u2_Link.STL" />
      </geometry>
      <material
        name="">
        <color
          rgba="0.792156862745098 0.819607843137255 0.933333333333333 1" />
      </material>
    </visual>
    <collision>
      <origin
        xyz="0 0 0"
        rpy="0 0 0" />
      <geometry>
        <mesh
          filename="package://trailer_description/meshes/u2_Link.STL" />
      </geometry>
    </collision>
  </link>
  <joint
    name="u2_joint"
    type="fixed">
    <origin
      xyz="-2.16 0.26 0.05"
      rpy="0 0 3.1416" />
    <parent
      link="base_link" />
    <child
      link="u2_Link" />
    <axis
      xyz="0 0 0" />
  </joint>
  <link
    name="u3_Link">
    <inertial>
      <origin
        xyz="2.22044604925031E-16 0 0"
        rpy="0 0 0" />
      <mass
        value="0.00176714586764422" />
      <inertia
        ixx="4.97009775274937E-08"
        ixy="-6.61984950467753E-23"
        ixz="6.44944990373324E-23"
        iyy="3.95767043274481E-08"
        iyz="-1.03497225198971E-37"
        izz="3.95767043274481E-08" />
    </inertial>
    <visual>
      <origin
        xyz="0 0 0"
        rpy="0 0 0" />
      <geometry>
        <mesh
          filename="package://trailer_description/meshes/u3_Link.STL" />
      </geometry>
      <material
        name="">
        <color
          rgba="0.792156862745098 0.819607843137255 0.933333333333333 1" />
      </material>
    </visual>
    <collision>
      <origin
        xyz="0 0 0"
        rpy="0 0 0" />
      <geometry>
        <mesh
          filename="package://trailer_description/meshes/u3_Link.STL" />
      </geometry>
    </collision>
  </link>
  <joint
    name="u3_joint"
    type="fixed">
    <origin
      xyz="-2.16 -0.26 0.05"
      rpy="0 0 3.1416" />
    <parent
      link="base_link" />
    <child
      link="u3_Link" />
    <axis
      xyz="0 0 0" />
  </joint>
  <link
    name="u4_Link">
    <inertial>
      <origin
        xyz="2.22044604925031E-16 0 0"
        rpy="0 0 0" />
      <mass
        value="0.00176714586764422" />
      <inertia
        ixx="4.97009775274937E-08"
        ixy="6.61984950467755E-23"
        ixz="-2.20581496680827E-24"
        iyy="3.95767043274481E-08"
        iyz="1.10592535436423E-38"
        izz="3.95767043274481E-08" />
    </inertial>
    <visual>
      <origin
        xyz="0 0 0"
        rpy="0 0 0" />
      <geometry>
        <mesh
          filename="package://trailer_description/meshes/u4_Link.STL" />
      </geometry>
      <material
        name="">
        <color
          rgba="0.792156862745098 0.819607843137255 0.933333333333333 1" />
      </material>
    </visual>
    <collision>
      <origin
        xyz="0 0 0"
        rpy="0 0 0" />
      <geometry>
        <mesh
          filename="package://trailer_description/meshes/u4_Link.STL" />
      </geometry>
    </collision>
  </link>
  <joint
    name="u4_joint"
    type="fixed">
    <origin
      xyz="-2.16 -0.6125 0.05"
      rpy="0 0 3.1416" />
    <parent
      link="base_link" />
    <child
      link="u4_Link" />
    <axis
      xyz="0 0 0" />
  </joint>
  <link
    name="depth_camera_link">
    <inertial>
      <origin
        xyz="-0.698188658539394 8.97578938885925E-17 0.0335521985627969"
        rpy="0 0 0" />
      <mass
        value="8787.20820689569" />
      <inertia
        ixx="2433.19755884074"
        ixy="-1.08003666773882E-12"
        ixz="892.312824904581"
        iyy="50275.0652757728"
        iyz="-1.42105836646589E-14"
        izz="51203.3820021919" />
    </inertial>
    <visual>
      <origin
        xyz="0 0 0"
        rpy="0 0 0" />
      <geometry>
        <mesh
          filename="package://trailer_description/meshes/depth_camera_link.STL" />
      </geometry>
      <material
        name="">
        <color
          rgba="1 1 1 1" />
      </material>
    </visual>
    <collision>
      <origin
        xyz="0 0 0"
        rpy="0 0 0" />
      <geometry>
        <mesh
          filename="package://trailer_description/meshes/depth_camera_link.STL" />
      </geometry>
    </collision>
  </link>
  <joint
    name="depth_camera_joint"
    type="fixed">
    <origin
      xyz="-2.16 0 0.414953113963299"
      rpy="0 0 3.14159265358979" />
    <parent
      link="base_link" />
    <child
      link="depth_camera_link" />
    <axis
      xyz="0 0 0" />
  </joint>
</robot>