<?xml version="1.0" encoding="utf-8"?>
<!-- This URDF was automatically created by SolidWorks to URDF Exporter! Originally created by Stephen Brawner (brawner@gmail.com) 
     Commit Version: 1.6.0-4-g7f85cfe  Build Version: 1.6.7995.38578
     For more information, please see http://wiki.ros.org/sw_urdf_exporter -->
<robot
  name="trailer_description">
  <link
    name="base_link">
    <inertial>
      <origin
        xyz="0.0151794504413043 -2.70548710772098E-16 0.504333281484515"
        rpy="0 0 0" />
      <mass
        value="5623.96238078164" />
      <inertia
        ixx="1505.2735842584"
        ixy="2.80968637770799E-14"
        ixz="-96.1203292275202"
        iyy="7932.64531285604"
        iyz="-2.5937462802081E-14"
        izz="8447.43080900142" />
    </inertial>
    <visual>
      <origin
        xyz="0 0 0"
        rpy="0 0 0" />
      <geometry>
        <mesh
          filename="package://trailer_description/meshes/base_link.STL" />
      </geometry>
      <material
        name="">
        <color
          rgba="0.792156862745098 0.819607843137255 0.933333333333333 1" />
      </material>
    </visual>
    <collision>
      <origin
        xyz="0 0 0"
        rpy="0 0 0" />
      <geometry>
        <mesh
          filename="package://trailer_description/meshes/base_link.STL" />
      </geometry>
    </collision>
  </link>
  <link
    name="steer_left">
    <inertial>
      <origin
        xyz="0 0 1.11022302462516E-16"
        rpy="0 0 0" />
      <mass
        value="1.48283173249438" />
      <inertia
        ixx="0.0113467519863581"
        ixy="4.92526541296846E-36"
        ixz="0"
        iyy="0.00118626538599551"
        iyz="4.00998451212503E-35"
        izz="0.0113467519863581" />
    </inertial>
    <visual>
      <origin
        xyz="0 0 0"
        rpy="0 0 0" />
      <geometry>
        <mesh
          filename="package://trailer_description/meshes/steer_left.STL" />
      </geometry>
      <material
        name="">
        <color
          rgba="0.792156862745098 0.819607843137255 0.933333333333333 1" />
      </material>
    </visual>
    <collision>
      <origin
        xyz="0 0 0"
        rpy="0 0 0" />
      <geometry>
        <mesh
          filename="package://trailer_description/meshes/steer_left.STL" />
      </geometry>
    </collision>
  </link>
  <joint
    name="steer_left_joint"
    type="revolute">
    <origin
      xyz="1.46 0.6125 0"
      rpy="0 0 0" />
    <parent
      link="base_link" />
    <child
      link="steer_left" />
    <axis
      xyz="0 0 -1" />
    <limit
      lower="-0.6"
      upper="0.6"
      effort="50"
      velocity="31.4" />
  </joint>
  <link
    name="front_left_wheel">
    <inertial>
      <origin
        xyz="0 0 -1.11022302462516E-16"
        rpy="0 0 0" />
      <mass
        value="74.1907633489725" />
      <inertia
        ixx="2.08218966287404"
        ixy="6.07695317678125E-17"
        ixz="-3.14934790723029E-18"
        iyy="3.08830412900736"
        iyz="3.93136225252298E-18"
        izz="2.08218966287404" />
    </inertial>
    <visual>
      <origin
        xyz="0 0 0"
        rpy="0 0 0" />
      <geometry>
        <mesh
          filename="package://trailer_description/meshes/front_left_wheel.STL" />
      </geometry>
      <material
        name="">
        <color
          rgba="0.792156862745098 0.819607843137255 0.933333333333333 1" />
      </material>
    </visual>
    <collision>
      <origin
        xyz="0 0 0"
        rpy="0 0 0" />
      <geometry>
        <mesh
          filename="package://trailer_description/meshes/front_left_wheel.STL" />
      </geometry>
    </collision>
  </link>
  <joint
    name="front_left_wheel_joint"
    type="continuous">
    <origin
      xyz="0 0 0"
      rpy="0 0 0" />
    <parent
      link="steer_left" />
    <child
      link="front_left_wheel" />
    <axis
      xyz="0 1 0" />
    <limit
      lower="0"
      upper="0"
      effort="100"
      velocity="31.4" />
  </joint>
  <link
    name="steer_right">
    <inertial>
      <origin
        xyz="0 0 1.11022302462516E-16"
        rpy="0 0 0" />
      <mass
        value="1.48283173249438" />
      <inertia
        ixx="0.0113467519863581"
        ixy="4.92526541296846E-36"
        ixz="0"
        iyy="0.00118626538599551"
        iyz="4.00998451212503E-35"
        izz="0.0113467519863581" />
    </inertial>
    <visual>
      <origin
        xyz="0 0 0"
        rpy="0 0 0" />
      <geometry>
        <mesh
          filename="package://trailer_description/meshes/steer_right.STL" />
      </geometry>
      <material
        name="">
        <color
          rgba="0.792156862745098 0.819607843137255 0.933333333333333 1" />
      </material>
    </visual>
    <collision>
      <origin
        xyz="0 0 0"
        rpy="0 0 0" />
      <geometry>
        <mesh
          filename="package://trailer_description/meshes/steer_right.STL" />
      </geometry>
    </collision>
  </link>
  <joint
    name="steer_right_joint"
    type="revolute">
    <origin
      xyz="1.46 -0.6125 0"
      rpy="0 0 0" />
    <parent
      link="base_link" />
    <child
      link="steer_right" />
    <axis
      xyz="0 0 1" />
    <limit
      lower="-0.6"
      upper="0.6"
      effort="50"
      velocity="31.4" />
  </joint>
  <link
    name="front_right_wheel">
    <inertial>
      <origin
        xyz="0 0 -1.11022302462516E-16"
        rpy="0 0 0" />
      <mass
        value="74.1907633489725" />
      <inertia
        ixx="2.08218966287404"
        ixy="6.07695317678125E-17"
        ixz="1.71424910145489E-17"
        iyy="3.08830412900736"
        iyz="1.83241460922682E-18"
        izz="2.08218966287404" />
    </inertial>
    <visual>
      <origin
        xyz="0 0 0"
        rpy="0 0 0" />
      <geometry>
        <mesh
          filename="package://trailer_description/meshes/front_right_wheel.STL" />
      </geometry>
      <material
        name="">
        <color
          rgba="0.792156862745098 0.819607843137255 0.933333333333333 1" />
      </material>
    </visual>
    <collision>
      <origin
        xyz="0 0 0"
        rpy="0 0 0" />
      <geometry>
        <mesh
          filename="package://trailer_description/meshes/front_right_wheel.STL" />
      </geometry>
    </collision>
  </link>
  <joint
    name="front_right_wheel_joint"
    type="continuous">
    <origin
      xyz="0 0 0"
      rpy="0 0 0" />
    <parent
      link="steer_right" />
    <child
      link="front_right_wheel" />
    <axis
      xyz="0 1 0" />
    <limit
      lower="0"
      upper="0"
      effort="100"
      velocity="31.4" />
  </joint>
  <link
    name="rear_left_wheel">
    <inertial>
      <origin
        xyz="0 -1.11022302462516E-16 0"
        rpy="0 0 0" />
      <mass
        value="74.1907633489725" />
      <inertia
        ixx="2.08218966287404"
        ixy="-3.48598814788576E-15"
        ixz="9.86076131526265E-32"
        iyy="3.08830412900736"
        iyz="-1.23785934175428E-30"
        izz="2.08218966287404" />
    </inertial>
    <visual>
      <origin
        xyz="0 0 0"
        rpy="0 0 0" />
      <geometry>
        <mesh
          filename="package://trailer_description/meshes/rear_left_wheel.STL" />
      </geometry>
      <material
        name="">
        <color
          rgba="0.792156862745098 0.819607843137255 0.933333333333333 1" />
      </material>
    </visual>
    <collision>
      <origin
        xyz="0 0 0"
        rpy="0 0 0" />
      <geometry>
        <mesh
          filename="package://trailer_description/meshes/rear_left_wheel.STL" />
      </geometry>
    </collision>
  </link>
  <joint
    name="rear_left_wheel_joint"
    type="continuous">
    <origin
      xyz="-1.17 0.6125 0"
      rpy="0 0 0" />
    <parent
      link="base_link" />
    <child
      link="rear_left_wheel" />
    <axis
      xyz="0 1 0" />
    <limit
      lower="0"
      upper="0"
      effort="100"
      velocity="31.4" />
  </joint>
  <link
    name="rear_right_wheel">
    <inertial>
      <origin
        xyz="0 1.11022302462516E-16 0"
        rpy="0 0 0" />
      <mass
        value="74.1907633489725" />
      <inertia
        ixx="2.08218966287404"
        ixy="3.48598814788576E-15"
        ixz="9.86076131526265E-32"
        iyy="3.08830412900736"
        iyz="1.22529057414273E-30"
        izz="2.08218966287404" />
    </inertial>
    <visual>
      <origin
        xyz="0 0 0"
        rpy="0 0 0" />
      <geometry>
        <mesh
          filename="package://trailer_description/meshes/rear_right_wheel.STL" />
      </geometry>
      <material
        name="">
        <color
          rgba="0.792156862745098 0.819607843137255 0.933333333333333 1" />
      </material>
    </visual>
    <collision>
      <origin
        xyz="0 0 0"
        rpy="0 0 0" />
      <geometry>
        <mesh
          filename="package://trailer_description/meshes/rear_right_wheel.STL" />
      </geometry>
    </collision>
  </link>
  <joint
    name="rear_right_wheel_joint"
    type="continuous">
    <origin
      xyz="-1.17 -0.6125 0"
      rpy="0 0 0" />
    <parent
      link="base_link" />
    <child
      link="rear_right_wheel" />
    <axis
      xyz="0 1 0" />
    <limit
      lower="0"
      upper="0"
      effort="100"
      velocity="31.4" />
  </joint>
  <link
    name="trailer">
    <inertial>
      <origin
        xyz="-2.06473943000056 -9.58261906684124E-17 0.256889099220807"
        rpy="0 0 0" />
      <mass
        value="2715.11151397176" />
      <inertia
        ixx="634.919956534306"
        ixy="7.70909607408193E-14"
        ixz="9.2945345694552"
        iyy="1640.30654615615"
        iyz="5.74506370494421E-15"
        izz="2004.11171155846" />
    </inertial>
    <visual>
      <origin
        xyz="0 0 0"
        rpy="0 0 0" />
      <geometry>
        <mesh
          filename="package://trailer_description/meshes/trailer.STL" />
      </geometry>
      <material
        name="">
        <color
          rgba="0.792156862745098 0.819607843137255 0.933333333333333 1" />
      </material>
    </visual>
    <collision>
      <origin
        xyz="0 0 0"
        rpy="0 0 0" />
      <geometry>
        <mesh
          filename="package://trailer_description/meshes/trailer.STL" />
      </geometry>
    </collision>
  </link>
  <joint
    name="trailer_joint"
    type="revolute">
    <origin
      xyz="-2.46 0 0.15"
      rpy="0 0 0" />
    <parent
      link="base_link" />
    <child
      link="trailer" />
    <axis
      xyz="0 0 -1" />
    <limit
      lower="-1"
      upper="1"
      effort="200"
      velocity="0.5" />
  </joint>
  <link
    name="t_left_wheel">
    <inertial>
      <origin
        xyz="0 0 0"
        rpy="0 0 0" />
      <mass
        value="74.1907633489725" />
      <inertia
        ixx="2.08218966287404"
        ixy="1.54577203395557E-16"
        ixz="-2.7725470652962E-17"
        iyy="3.08830412900736"
        iyz="1.28966559951787E-17"
        izz="2.08218966287404" />
    </inertial>
    <visual>
      <origin
        xyz="0 0 0"
        rpy="0 0 0" />
      <geometry>
        <mesh
          filename="package://trailer_description/meshes/t_left_wheel.STL" />
      </geometry>
      <material
        name="">
        <color
          rgba="0.792156862745098 0.819607843137255 0.933333333333333 1" />
      </material>
    </visual>
    <collision>
      <origin
        xyz="0 0 0"
        rpy="0 0 0" />
      <geometry>
        <mesh
          filename="package://trailer_description/meshes/t_left_wheel.STL" />
      </geometry>
    </collision>
  </link>
  <joint
    name="t_left_wheel_joint"
    type="continuous">
    <origin
      xyz="-2.2086 0.6125 -0.15"
      rpy="0 0 0" />
    <parent
      link="trailer" />
    <child
      link="t_left_wheel" />
    <axis
      xyz="0 -1 0" />
    <limit
      lower="0"
      upper="0"
      effort="100"
      velocity="31.4" />
  </joint>
  <link
    name="t_right_wheel">
    <inertial>
      <origin
        xyz="0 0 0"
        rpy="0 0 0" />
      <mass
        value="74.1907633489725" />
      <inertia
        ixx="2.08218966287404"
        ixy="-1.11352546000202E-18"
        ixz="6.83908165898515E-17"
        iyy="3.08830412900736"
        iyz="1.38630298064868E-17"
        izz="2.08218966287404" />
    </inertial>
    <visual>
      <origin
        xyz="0 0 0"
        rpy="0 0 0" />
      <geometry>
        <mesh
          filename="package://trailer_description/meshes/t_right_wheel.STL" />
      </geometry>
      <material
        name="">
        <color
          rgba="0.792156862745098 0.819607843137255 0.933333333333333 1" />
      </material>
    </visual>
    <collision>
      <origin
        xyz="0 0 0"
        rpy="0 0 0" />
      <geometry>
        <mesh
          filename="package://trailer_description/meshes/t_right_wheel.STL" />
      </geometry>
    </collision>
  </link>
  <joint
    name="t_right_wheel_joint"
    type="continuous">
    <origin
      xyz="-2.2086 -0.6125 -0.15"
      rpy="0 0 0" />
    <parent
      link="trailer" />
    <child
      link="t_right_wheel" />
    <axis
      xyz="0 -1 0" />
    <limit
      lower="0"
      upper="0"
      effort="100"
      velocity="31.4" />
  </joint>
  <link
    name="u1_Link">
    <inertial>
      <origin
        xyz="2.22044604925031E-16 0 0"
        rpy="0 0 0" />
      <mass
        value="0.00176714586764422" />
      <inertia
        ixx="4.97009775274937E-08"
        ixy="6.44944990373328E-23"
        ixz="-1.28060738442034E-40"
        iyy="3.95767043274481E-08"
        iyz="9.95682444457783E-55"
        izz="3.95767043274481E-08" />
    </inertial>
    <visual>
      <origin
        xyz="0 0 0"
        rpy="0 0 0" />
      <geometry>
        <mesh
          filename="package://trailer_description/meshes/u1_Link.STL" />
      </geometry>
      <material
        name="">
        <color
          rgba="0.792156862745098 0.819607843137255 0.933333333333333 1" />
      </material>
    </visual>
    <collision>
      <origin
        xyz="0 0 0"
        rpy="0 0 0" />
      <geometry>
        <mesh
          filename="package://trailer_description/meshes/u1_Link.STL" />
      </geometry>
    </collision>
  </link>
  <joint
    name="u1_joint"
    type="fixed">
    <origin
      xyz="-2.16 0.6125 0.05"
      rpy="0 0 3.1416" />
    <parent
      link="base_link" />
    <child
      link="u1_Link" />
    <axis
      xyz="0 0 0" />
  </joint>
  <link
    name="u2_Link">
    <inertial>
      <origin
        xyz="4.44089209850063E-16 0 0"
        rpy="0 0 0" />
      <mass
        value="0.00176714586764422" />
      <inertia
        ixx="4.97009775274937E-08"
        ixy="-6.61984950467753E-23"
        ixz="6.44944990373324E-23"
        iyy="3.95767043274481E-08"
        iyz="-1.03497225198971E-37"
        izz="3.95767043274481E-08" />
    </inertial>
    <visual>
      <origin
        xyz="0 0 0"
        rpy="0 0 0" />
      <geometry>
        <mesh
          filename="package://trailer_description/meshes/u2_Link.STL" />
      </geometry>
      <material
        name="">
        <color
          rgba="0.792156862745098 0.819607843137255 0.933333333333333 1" />
      </material>
    </visual>
    <collision>
      <origin
        xyz="0 0 0"
        rpy="0 0 0" />
      <geometry>
        <mesh
          filename="package://trailer_description/meshes/u2_Link.STL" />
      </geometry>
    </collision>
  </link>
  <joint
    name="u2_joint"
    type="fixed">
    <origin
      xyz="-2.16 0.26 0.05"
      rpy="0 0 3.1416" />
    <parent
      link="base_link" />
    <child
      link="u2_Link" />
    <axis
      xyz="0 0 0" />
  </joint>
  <link
    name="u3_Link">
    <inertial>
      <origin
        xyz="2.22044604925031E-16 0 0"
        rpy="0 0 0" />
      <mass
        value="0.00176714586764422" />
      <inertia
        ixx="4.97009775274937E-08"
        ixy="-6.61984950467753E-23"
        ixz="6.44944990373324E-23"
        iyy="3.95767043274481E-08"
        iyz="-1.03497225198971E-37"
        izz="3.95767043274481E-08" />
    </inertial>
    <visual>
      <origin
        xyz="0 0 0"
        rpy="0 0 0" />
      <geometry>
        <mesh
          filename="package://trailer_description/meshes/u3_Link.STL" />
      </geometry>
      <material
        name="">
        <color
          rgba="0.792156862745098 0.819607843137255 0.933333333333333 1" />
      </material>
    </visual>
    <collision>
      <origin
        xyz="0 0 0"
        rpy="0 0 0" />
      <geometry>
        <mesh
          filename="package://trailer_description/meshes/u3_Link.STL" />
      </geometry>
    </collision>
  </link>
  <joint
    name="u3_joint"
    type="fixed">
    <origin
      xyz="-2.16 -0.26 0.05"
      rpy="0 0 3.1416" />
    <parent
      link="base_link" />
    <child
      link="u3_Link" />
    <axis
      xyz="0 0 0" />
  </joint>
  <link
    name="u4_Link">
    <inertial>
      <origin
        xyz="2.22044604925031E-16 0 0"
        rpy="0 0 0" />
      <mass
        value="0.00176714586764422" />
      <inertia
        ixx="4.97009775274937E-08"
        ixy="6.61984950467755E-23"
        ixz="-2.20581496680827E-24"
        iyy="3.95767043274481E-08"
        iyz="1.10592535436423E-38"
        izz="3.95767043274481E-08" />
    </inertial>
    <visual>
      <origin
        xyz="0 0 0"
        rpy="0 0 0" />
      <geometry>
        <mesh
          filename="package://trailer_description/meshes/u4_Link.STL" />
      </geometry>
      <material
        name="">
        <color
          rgba="0.792156862745098 0.819607843137255 0.933333333333333 1" />
      </material>
    </visual>
    <collision>
      <origin
        xyz="0 0 0"
        rpy="0 0 0" />
      <geometry>
        <mesh
          filename="package://trailer_description/meshes/u4_Link.STL" />
      </geometry>
    </collision>
  </link>
  <joint
    name="u4_joint"
    type="fixed">
    <origin
      xyz="-2.16 -0.6125 0.05"
      rpy="0 0 3.1416" />
    <parent
      link="base_link" />
    <child
      link="u4_Link" />
    <axis
      xyz="0 0 0" />
  </joint>
  <link
    name="depth_camera_link">
    <inertial>
      <origin
        xyz="-0.698189709402004 5.98392135211463E-17 0.033552049821109"
        rpy="0 0 0" />
      <mass
        value="8787.20320689569" />
      <inertia
        ixx="2433.19483459516"
        ixy="-3.12650225766219E-13"
        ixz="892.315238754295"
        iyy="50275.0478791783"
        iyz="-2.84212140029952E-14"
        izz="51203.3625667597" />
    </inertial>
    <visual>
      <origin
        xyz="0 0 0"
        rpy="0 0 0" />
      <geometry>
        <mesh
          filename="package://trailer_description/meshes/depth_camera_link.STL" />
      </geometry>
      <material
        name="">
        <color
          rgba="1 1 1 1" />
      </material>
    </visual>
    <collision>
      <origin
        xyz="0 0 0"
        rpy="0 0 0" />
      <geometry>
        <mesh
          filename="package://trailer_description/meshes/depth_camera_link.STL" />
      </geometry>
    </collision>
  </link>
  <joint
    name="depth_camera_joint"
    type="fixed">
    <origin
      xyz="-2.16 0 0.41495"
      rpy="0 0 3.1416" />
    <parent
      link="base_link" />
    <child
      link="depth_camera_link" />
    <axis
      xyz="0 0 0" />
  </joint>
</robot>